Workbook

Sheet Cover
D14: Typ dokumentu | F14: Plik z danymi roku bazowego
D18: Cel powstania | F18: Wprowadzenie topologii popytów i wartości popytów
D22: Data powstania | F22: 45173
D25: Ostatnia aktualizacja | F25: 45289
D28: Autor(zy) | F28: Artur Wyrwa
F29: Maciej Raczyński
D32: Osoba kontaktowa | F32: Artur Wyrwa
F33: awyrwa@agh.edu.pl

Sheet Metadane
D4: Metadane
D6: Wersja modelu na potrzeby scenariuszy INTG_3

Sheet SEC_Comm
B2: * Zdefiniuj dobra wykorzystywane w arkuszu
B4: *Surowce
B6: ~FI_Comm
B7: Csets | C7: Region | D7: CommName | E7: CommDesc | F7: Unit | G7: LimType | H7: CTSLvl | I7: PeakTS | J7: Ctype
B8: * Przynależność do zbioru dóbr | C8: Region | D8: Nazwa dobra | E8: Opis dobra | F8: Jednostka | G8: Znak w równaniu bilansu | H8: Poziom podokresów | I8: Monitorowanie szczytu | J8: Wskaźnik energii elektrycznej
B9: DEM | C9: PL | D9: ELC_FIN_CONS | E9: Final electricicty consumption - other sectors | F9: PJ | H9: DAYNITE
B10: DEM | C10: PL | D10: HT_DH_OTH_FIN_CONS | E10: Derived heat consumption - other sectors | F10: PJ | H10: DAYNITE
B11: DEM | C11: PL | D11: DMD_NEW_RSD_DTH | E11: Residential Dwelling - Detached houses | F11: 000units
B12: DEM | C12: PL | D12: DMD_NEW_RSD_SDTH | E12: Residential Dwelling - Semi-detached houses | F12: 000units
B13: DEM | C13: PL | D13: DMD_NEW_RSD_FLAT | E13: Residential Dwelling - Flats | F13: 000units
B15: DEM | C15: PL | D15: HT_IND_FIN_CONS | E15: Derrived heat consumption - industry | F15: PJ

Sheet SEC_Processes
B2: * Zdefiniuj procesy wykorzystywane w arkuszu
B4: *Procesy
B6: ~FI_Process
B7: Sets | C7: Region | D7: TechName | E7: TechDesc | F7: Tact | G7: Tcap | H7: Tslvl | I7: PrimaryCG | J7: Vintage
B8: * Przynależność do zbioru procesów | C8: Nazwa regionu | D8: Nazwa technologii | E8: Opis technologii | F8: Jednostka aktywności | G8: Jednostka mocy | H8: Podokres aktywności procesu | I8: Przynależność do grupy głównej dóbr | J8: Śledzenie rocznika
B9: DMD | C9: PL | D9: ELC_FIN_TECH | E9: Processes of converting final energy into useful energy | F9: PJ | G9: PJa | H9: DAYNITE | J9: NO
B10: DMD | C10: PL | D10: HT_DH_FIN_TECH | E10: Processes of converting final energy into useful energy | F10: PJ | G10: PJa | H10: DAYNITE

Sheet END_USE_TECH
B2: *Technologie odbiorcze
E4: ~FI_T:PL
B5: TechName | C5: *TechDesc | D5: Comm-IN | E5: Comm-OUT | F5: Share-I~FX | G5: EFF | H5: CAP2ACT
B6: * Nazwa technologii | C6: Opis technologii | D6: Surowiec na wejściu | E6: Surowiec na wyjściu | F6: Udział w wejściu do procesu | G6: Sprawność | H6: Przelicznik mocy na aktywność
B7: =SEC_Processes!D9 -> ELC_FIN_TECH | D7: ELC_HV-HV | F7: 0.2448 | G7: 1 | H7: 1 | K7: Podział odpowiada zużyciu energii na poszczególnych poziomach napięć obecnie
D8: ELC_MV-MV | F8: 0.3636
D9: ELC_LV-LV | F9: 0.3916
E10: =SEC_Comm!D9 -> ELC_FIN_CONS
B11: =SEC_Processes!D10 -> HT_DH_FIN_TECH | D11: HT_DH | E11: =SEC_Comm!D10 -> HT_DH_OTH_FIN_CONS | G11: 1 | H11: 1
B13: \I: | D13: HT_DH_IND | E13: =SEC_Comm!D15 -> HT_IND_FIN_CONS | G13: 1 | H13: 1

Sheet HEAT_DEMAND
C1: * declare and characterize heat demands
C3: ~FI_T:DEMAND
C4: CommName | D4: Region | E4: 2020 | F4: 2025 | G4: 2030 | H4: 2035 | I4: 2040 | J4: 2045 | K4: 2050
C5: \I: | E5: PJ | F5: PJ | G5: PJ | H5: PJ | I5: PJ | J5: PJ | K5: PJ
C6: =SEC_Comm!D10 -> HT_DH_OTH_FIN_CONS | D6: PL | E6: =E19+E21-E31-E33 -> 0.036969444 | F6: =F19+F21-F31-F33 -> 0.036969444 | G6: =G19+G21-G31-G33 -> 0.036969444 | H6: =H19+H21-H31-H33 -> 0.036969444 | I6: =I19+I21-I31-I33 -> 0.036969444 | J6: =J19+J21-J31-J33 -> 0.036969444 | K6: =K19+K21-K31-K33 -> 0.036969444
C9: =SEC_Comm!D15 -> HT_IND_FIN_CONS | E9: =E17-E29 -> 1.668379 | F9: =F17-F29 -> 1.668379 | G9: =G17-G29 -> 1.668379 | H9: =H17-H29 -> 1.668379 | I9: =I17-I29 -> 1.668379 | J9: =J17-J29 -> 1.668379 | K9: =K17-K29 -> 1.668379
C11: IND_HT_OWN_USE
C12: total heat | E12: =E6+E9+E20 -> 154.20904 | F12: =F6+F9+F20 -> 154.20904 | G12: =G6+G9+G20 -> 154.20904 | H12: =H6+H9+H20 -> 154.20904 | I12: =I6+I9+I20 -> 154.20904 | J12: =J6+J9+J20 -> 154.20904 | K12: =K6+K9+K20 -> 154.20904
B14: T6 Polityka 2.1 | C14: ktoe | E14: 5748 | F14: 5436 | G14: 5090 | H14: 5080 | I14: 5132 | J14: 5101 | K14: 5101
B15: Final Heat demand residential & tertiary | E15: 240.65726 | F15: 227.59445 | G15: 213.10812 | H15: 212.68944 | I15: 214.86658 | J15: 213.56867 | K15: 213.56867
B17: Industry sector | E17: =GUS_2020_HT_ELC!B106 -> 35.79714 | F17: =E17 -> 35.79714 | G17: =F17 -> 35.79714 | H17: =G17 -> 35.79714 | I17: =H17 -> 35.79714 | J17: =I17 -> 35.79714 | K17: =J17 -> 35.79714
B18: Transport sector
B19: Commercial & public services | E19: =GUS_2020_HT_ELC!B128 -> 45.719856 | F19: =E19 -> 45.719856 | G19: =F19 -> 45.719856 | H19: =G19 -> 45.719856 | I19: =H19 -> 45.719856 | J19: =I19 -> 45.719856 | K19: =J19 -> 45.719856
B20: Households | E20: 152.5037 | F20: =E20 -> 152.5037 | G20: =F20 -> 152.5037 | H20: =G20 -> 152.5037 | I20: =H20 -> 152.5037 | J20: =I20 -> 152.5037 | K20: =J20 -> 152.5037
B21: Agriculture & forestry | E21: =GUS_2020_HT_ELC!B130 -> 0.795492 | F21: =E21 -> 0.795492 | G21: =F21 -> 0.795492 | H21: =G21 -> 0.795492 | I21: =H21 -> 0.795492 | J21: =I21 -> 0.795492 | K21: =J21 -> 0.795492
B22: Other | E22: 0 | F22: 1 | G22: 2 | H22: 3 | I22: 4 | J22: 5 | K22: 6
B24: ODEJMOWANIE ZUŻYCIA FINALNEGO Z ZAMODELOWANYCH SEKTORÓW [PJ] | L24: =E12/L25 -> 0.85222502 | N24: Table Name: | O24: Unsaved_172226
B25: Residential | C25: Bez linkowania do arkuszy sektorowych, żeby się nie rozjechało kiedy będziemy zmieniać. Docelowo powinno pobierać dane z arkuszy sektorowych - Maciek | L25: =E12+E40 -> 180.94874 | N25: Attribute | O25: Process | P25: Commodity | Q25: GrandTotal
B26: Hot Water | E26: 58.266514 | F26: 58.266514 | G26: 58.266514 | H26: 58.266514 | I26: 58.266514 | J26: 58.266514 | K26: 58.266514 | N26: VAR_FIn | O26: HT_TRANSF_IND | P26: HT_HT_I | Q26: 40.404751
B27: Space Heating | E27: 107.3622 | F27: 107.3622 | G27: 107.3622 | H27: 107.3622 | I27: 107.3622 | J27: 107.3622 | K27: 107.3622 | N27: VAR_FIn | O27: HT_TRANSF_RSD | P27: HT_HT | Q27: 169.44855
B28: Industry | N28: VAR_FOut | O28: HT_TRANSF_IND | P28: HT_IND | Q28: 36.364276
B29: Other industry | E29: 34.128761 | F29: 34.128761 | G29: 34.128761 | H29: 34.128761 | I29: 34.128761 | J29: 34.128761 | K29: 34.128761 | N29: VAR_FOut | O29: HT_TRANSF_RSD | P29: HT_RSD | Q29: 152.5037
B30: Commercial
B31: Whole sector | E31: 45.70336 | F31: 45.70336 | G31: 45.70336 | H31: 45.70336 | I31: 45.70336 | J31: 45.70336 | K31: 45.70336
B32: Agriculture
B33: Whole sector | E33: 0.77501855 | F33: 0.77501855 | G33: 0.77501855 | H33: 0.77501855 | I33: 0.77501855 | J33: 0.77501855 | K33: 0.77501855
B34: TOTAL
E35: =SUM(E26:E34) -> 246.23585
B37: Final Heat demand other | E37: 0 | F37: 0 | G37: 0 | H37: 0 | I37: 0 | J37: 0 | K37: 0
B38: Total Final Heat demand [PJ] | E38: =E9+E19+E20+E21 -> 200.68742 | F38: =F9+F19+F20+F21 -> 200.68742 | G38: =G9+G19+G20+G21 -> 200.68742 | H38: =H9+H19+H20+H21 -> 200.68742 | I38: =I9+I19+I20+I21 -> 200.68742 | J38: =J9+J19+J20+J21 -> 200.68742 | K38: =K9+K19+K20+K21 -> 200.68742
B39: Demand of the DH conversion sector | E39: 21.5 | F39: 21.5 | G39: 21.5 | H39: 21.5 | I39: 21.5 | J39: 21.5 | K39: 21.5
B40: line losses | E40: 26.739696 | F40: 25.288272 | G40: 23.67868 | H40: 23.63216 | I40: 23.874064 | J40: 23.729852 | K40: 23.729852
B41: Net heat generation | E41: 288.89696 | F41: 274.38272 | G41: 258.2868 | H41: 257.8216 | I41: 260.24064 | J41: 258.79852 | K41: 258.79852
B42: own power plants consumption | E42: 7.8 | F42: 7.8 | G42: 7.8 | H42: 7.8 | I42: 7.8 | J42: 7.8 | K42: 7.8
B43: Gross DH heat generation | E43: 296.69696 | F43: 282.18272 | G43: 266.0868 | H43: 265.6216 | I43: 268.04064 | J43: 266.59852 | K43: 266.59852
B44: T8 brutto polityka | C44: ktoe | E44: 6721 | F44: 6626 | G44: 6204 | H44: 6153 | I44: 6204 | J44: 6187 | K44: 6187
C45: PJ | E45: 281.39483 | F45: 277.41737 | G45: 259.74907 | H45: 257.6138 | I45: 259.74907 | J45: 259.03732 | K45: 259.03732
B46: final / brutto polityka | E46: 0.85522988 | F46: 0.82040447 | G46: 0.82043843 | H46: 0.82561352 | I46: 0.82720825 | J46: 0.82447066 | K46: 0.82447066
B47: gross nasze - brutto polityka | C47: PJ | E47: 15.302132 | F47: 4.765352 | G47: 6.337728 | H47: 8.007796 | I47: 8.291568 | J47: 7.561204 | K47: 7.561204
B51: Total Final Heat demand [PJ] | E51: 240.65726 | F51: 227.59445 | G51: 213.10812 | H51: 212.68944 | I51: 214.86658 | J51: 213.56867 | K51: 213.56867
...

Sheet ELC_DEMAND
B1: * declare and characterize electricity demands | E1: =(E47-E45+E46)*3.6-E40 -> 17.133412
B3: ~FI_T:DEMAND
B4: CommName | C4: Region | D4: 2018 | E4: 2020 | F4: 2025 | G4: 2030 | H4: 2035 | I4: 2040 | J4: 2045 | K4: 2050
B5: \I: | D5: PJ | E5: PJ | F5: PJ | G5: PJ | H5: PJ | I5: PJ | J5: PJ | K5: PJ
B6: ELC_FIN_CONS | C6: PL | D6: 0 | E6: 0 | F6: =(F47-F45+F46)*3.6-F40 -> 88.654 | G6: =(G47-G45+G46)*3.6-G40 -> 137.26275 | H6: =(H47-H45+H46)*3.6-H40 -> 181.68534 | I6: =(I47-I45+I46)*3.6-I40 -> 227.11277 | J6: =(J47-J45+J46)*3.6-J40 -> 267.3067 | K6: =(K47-K45+K46)*3.6-K40 -> 309.94572
B8: IND_ELC_OWN_USE
E9: 548.37994
D10: =(D47+D46)*D12 -> 8.75 | E10: =(E47+E46)*E12 -> 8.4711864
D11: 8.75 | E11: 8.4711864
C12: 1 | D12: 0.056 | E12: 0.056 | F12: 0.055 | G12: 0.054 | H12: 0.053 | I12: 0.052 | J12: 0.051 | K12: 0.05
B13: T6 Polityka 2.1 | C13: ktoe | E13: 12152 | F13: 13041 | G13: 14202 | H13: 15349 | I13: 16520 | J13: 17566 | K13: 18670.4 | M13: PJ
B14: Final Electricity demand [TWh]: | D14: 136.5 | E14: 131.8 | F14: 151.66683 | G14: 165.16926 | H14: 178.50887 | I14: 192.1276 | J14: 204.29258 | K14: 217.13675 | M14: =E14*3.6 -> 474.48
B15: Industry sector | E15: =GUS_2020_HT_ELC!E106 -> 54.3121 | M15: =E15*3.6 -> 195.52356
B16: Transport sector | E16: =GUS_2020_HT_ELC!E120 -> 3.17499 | M16: =E16*3.6 -> 11.429964
B17: Commercial & public services | E17: =GUS_2020_HT_ELC!E128 -> 46.49674 | M17: =E17*3.6 -> 167.38826
B18: Households | E18: =GUS_2020_HT_ELC!E129 -> 30.0054 | M18: =E18*3.6 -> 108.01944
B19: Agriculture & forestry | E19: =GUS_2020_HT_ELC!E130 -> 1.83754 | M19: =E19*3.6 -> 6.615144
B20: Other | E20: =GUS_2020_HT_ELC!E131 -> 0.01163 | M20: =E20*3.6 -> 0.041868
B22: ODEJMOWANIE ZUŻYCIA FINALNEGO Z ZAMODELOWANYCH SEKTORÓW [PJ]
B23: Supply
B24: Own consumption | C24: Bez linkowania do arkuszy sektorowych, żeby się nie rozjechało kiedy będziemy zmieniać. Docelowo powinno pobierać dane z arkuszy sektorowych - Maciek Przeciągnięcie zużycia na razie na kolejne lata | E24: 4.85
B25: Oil Refinery | E25: 6.11
B26: Residential
B27: Electrical Appliances | E27: 82.02
B28: Cooking | E28: 11.45
B29: Hot Water | E29: 8.18
B30: Space Heating | E30: 5.11
B31: Industry
B32: Cement | E32: 6.89
B33: Other industry | E33: 192.56908
B34: Transport
B35: All modes | E35: 0.4122
B36: Commercial
B37: Whole sector | E37: 172.75704
B38: Agriculture
B39: Whole sector | E39: 6.5982712
B40: TOTAL | E40: =SUM(E24:E39) -> 496.94659 | F40: =E40 -> 496.94659 | G40: =F40 -> 496.94659 | H40: =G40 -> 496.94659 | I40: =H40 -> 496.94659 | J40: =I40 -> 496.94659 | K40: =J40 -> 496.94659
B44: Demand of the conversion sector | D44: 11 | E44: 11 | F44: 11 | G44: 11 | H44: 10 | I44: 9 | J44: 8 | K44: 7
B45: line losses (net gen * efe) | D45: 8.75 | E45: 8.4711864 | F45: 9.4673816 | G45: 10.056173 | H45: 10.550127 | I45: 11.032316 | J45: 11.408769 | K45: 11.796671
B46: import/export saldo | D46: =D66 -> 5.718 | E46: 13.224 | F46: 0 | G46: 0 | H46: 0 | I46: 0 | J46: 0 | K46: 0
...

Sheet TFM_DEMAND
B3: ~FI_T:DEMAND
B5: CommName | C5: Region | D5: 2020 | F5: 2021 | G5: 2025 | H5: 2030 | I5: 2035 | J5: 2040 | K5: 2045 | L5: 2050
B6: \I: | C6: Region | D6: PJ | F6: PJ | G6: PJ | H6: PJ | I6: PJ | J6: PJ | K6: PJ | L6: PJ
B7: TFM_HC_OUT | C7: PL | D7: 230.03012 | F7: 230.03012 | G7: 230.03012 | H7: 230.03012 | I7: 230.03012 | J7: 230.03012 | K7: 230.03012 | L7: 230.03012
B8: TFM_OTH_FUE_OUT | C8: PL | D8: 145.63671 | F8: 145.63671 | G8: 145.63671 | H8: 145.63671 | I8: 145.63671 | J8: 145.63671 | K8: 145.63671 | L8: 145.63671

Sheet RSD_DEMAND
D2: 15015.333
B3: ~FI_T:DEMAND
B4: CommName | C4: Region | D4: 2020 | E4: 2021 | F4: 2025 | G4: 2030 | H4: 2035 | I4: 2040 | J4: 2045 | K4: 2050
B5: \I: | C5: Region | F5: 000units | G5: 000units | H5: 000units | I5: 000units | J5: 000units | K5: 000units
B6: =SEC_Comm!D11 -> DMD_NEW_RSD_DTH | C6: PL | D6: 0 | E6: 0 | F6: =F18*F26 -> 318.66 | G6: =G18*G26 -> 185.18 | H6: =H18*H26 -> 229.83 | I6: =I18*I26 -> 181.24 | J6: =J18*J26 -> 246.606 | K6: =K18*K26 -> 215.685
B7: =SEC_Comm!D12 -> DMD_NEW_RSD_SDTH | C7: PL | D7: 0 | E7: 0 | F7: =F18*F27 -> 40.68 | G7: =G18*G27 -> 23.64 | H7: =H18*H27 -> 29.34 | I7: =I18*I27 -> 23.64 | J7: =J18*J27 -> 32.166 | K7: =K18*K27 -> 28.758
B8: =SEC_Comm!D13 -> DMD_NEW_RSD_FLAT | C8: PL | D8: 0 | E8: 0 | F8: =F18*F25 -> 318.66 | G8: =G18*G25 -> 185.18 | H8: =H18*H25 -> 229.83 | I8: =I18*I25 -> 189.12 | J8: =J18*J25 -> 257.328 | K8: =K18*K25 -> 234.857
F11: =SUM(F6:F8) -> 678 | G11: =SUM(G6:G8) -> 394 | H11: =SUM(H6:H8) -> 489 | I11: =SUM(I6:I8) -> 394 | J11: =SUM(J6:J8) -> 536.1 | K11: =SUM(K6:K8) -> 479.3
D17: aKPEiK | E17: 15016 | F17: 15694 | G17: 16088 | H17: 16577 | I17: 16971 | J17: 17507.1 | K17: 17986.4
F18: =F17-E17 -> 678 | G18: =G17-F17 -> 394 | H18: =H17-G17 -> 489 | I18: =I17-H17 -> 394 | J18: =J17-I17 -> 536.1 | K18: =K17-J17 -> 479.3
C25: Mieszkania w budynku wielorodzinnym Flats in multifamilty house | D25: 0.47 | E25: 0.47 | F25: 0.47 | G25: 0.47 | H25: 0.47 | I25: 0.48 | J25: 0.48 | K25: 0.49
C26: Budynki jednorodzinne wolnostojące Detached house | D26: 0.47 | E26: 0.47 | F26: 0.47 | G26: 0.47 | H26: 0.47 | I26: 0.46 | J26: 0.46 | K26: 0.45
C27: Mieszkania w budynku jednorodzinnym w zabudowie szeregowej Semi-detached house | D27: 0.06 | E27: 0.06 | F27: 0.06 | G27: 0.06 | H27: 0.06 | I27: 0.06 | J27: 0.06 | K27: 0.06
D49: Ogółem 12 776 13 471 13 962 15 016 | G49: 15016 | H49: 15694 | I49: 16088 | J49: 16577 | K49: 16971
D50: 15694
D51: 16088
D52: 16577
D53: 16971

Sheet IND_DEMAND
B1: * declare and characterize electricity demands | E1: =E5-$D$5 -> 5 | F1: 5 | G1: 5 | H1: 5 | I1: 5 | J1: 5
E2: 0.03 | F2: 0.03 | G2: 0.02 | H2: 0.02 | I2: 0.02 | J2: 0.02
B4: ~FI_T:DEMAND
B5: CommName | C5: Region | D5: 2020 | E5: 2025 | F5: 2030 | G5: 2035 | H5: 2040 | I5: 2045 | J5: 2050
B6: \I: | D6: IPI | E6: IPI | F6: IPI | G6: IPI | H6: IPI | I6: IPI | J6: IPI
B7: IND_OTH | C7: PL | D7: 100 | E7: =ROUND($D$7*(1+E2)^E1,3) -> 115.927 | F7: =ROUND($E$7*(1+F2)^F1,3) -> 134.391 | G7: =ROUND($F$7*(1+G2)^G1,3) -> 148.379 | H7: =ROUND($G$7*(1+H2)^H1,3) -> 163.822 | I7: =ROUND($H$7*(1+I2)^I1,3) -> 180.873 | J7: =ROUND($I$7*(1+J2)^J1,3) -> 199.698
E9: =(E7-$D7)/$D7 -> 0.15927 | F9: =(F7-$D7)/$D7 -> 0.34391 | G9: =(G7-$D7)/$D7 -> 0.48379 | H9: =(H7-$D7)/$D7 -> 0.63822 | I9: =(I7-$D7)/$D7 -> 0.80873 | J9: =(J7-$D7)/$D7 -> 0.99698
B11: ~FI_T:DEMAND
B12: CommName | C12: Region | D12: 2020
B13: \I: | D13: PJ
B14: IND_HT_OWN_USE_DEM | C14: PL | D14: 1
C16: Production | D16: Sales | E16: Own consumption | F16: % sales
B17: HPL_IND | C17: 116.8 | D17: =GUS_2020_HT_ELC!B56 -> 4.898556 | E17: =C17-D17 -> 111.90144 | F17: =D17/C17 -> 0.041939692
B18: CHP_IND | C18: 106.96 | D18: =GUS_2020_HT_ELC!B55 -> 16.579728 | E18: =C18-D18 -> 90.380272 | F18: =D18/C18 -> 0.15500868
E19: =SUM(E17:E18) -> 202.28172
C22: 100 | E22: 100 | F22: 100 | G22: 100 | H22: 100 | I22: 100 | J22: 100
C23: 100 | E23: 100 | F23: 100 | G23: 100 | H23: 100 | I23: 100 | J23: 100
B24: IND_TEX | C24: 100 | E24: 100 | F24: 100 | G24: 100 | H24: 100 | I24: 100 | J24: 100
B25: IND_PPP | C25: 100 | E25: 100 | F25: 100 | G25: 100 | H25: 100 | I25: 100 | J25: 100
B26: IND_CHM | C26: 100 | E26: 100 | F26: 100 | G26: 100 | H26: 100 | I26: 100 | J26: 100
B27: IND_GLASS | C27: 100 | E27: 100 | F27: 100 | G27: 100 | H27: 100 | I27: 100 | J27: 100
B28: IND_NMM | C28: 100 | E28: 100 | F28: 100 | G28: 100 | H28: 100 | I28: 100 | J28: 100
B29: IND_FER | C29: 100 | E29: 100 | F29: 100 | G29: 100 | H29: 100 | I29: 100 | J29: 100
B30: IND_NFM | C30: 100 | E30: 100 | F30: 100 | G30: 100 | H30: 100 | I30: 100 | J30: 100
B31: IND_MAN | C31: 100 | E31: 100 | F31: 100 | G31: 100 | H31: 100 | I31: 100 | J31: 100

Sheet AGR_DEMAND
B3: ~FI_T:DEMAND
B4: CommName | C4: Region | D4: 2020 | E4: 2025 | F4: 2030 | G4: 2035 | H4: 2040 | I4: 2045 | J4: 2050
B5: \I: | D5: IPI | E5: IPI | F5: IPI | G5: IPI | H5: IPI | I5: IPI | J5: IPI
B6: AGR_DEM | C6: PL | D6: 100 | E6: 100 | F6: 100 | G6: 100 | H6: 100 | I6: 100 | J6: 100
B7: \I: | D7: thousands of animals
B8: AGR_DEM_LIV_CAT_DAIRY | C8: PL | D8: =D76/1000 -> 2391.308 | E8: =D8 -> 2391.308 | F8: =E8 -> 2391.308 | G8: =F8 -> 2391.308 | H8: =G8 -> 2391.308 | I8: =H8 -> 2391.308 | J8: =I8 -> 2391.308
B9: AGR_DEM_LIV_CAT_NON-DAIRY | C9: PL | D9: =(C76-D76)/1000 -> 3887.588 | E9: =D9 -> 3887.588 | F9: =E9 -> 3887.588 | G9: =F9 -> 3887.588 | H9: =G9 -> 3887.588 | I9: =H9 -> 3887.588 | J9: =I9 -> 3887.588
B10: AGR_DEM_LIV_SHEEP | C10: PL | D10: =G76/1000 -> 277.85 | E10: =D10 -> 277.85 | F10: =E10 -> 277.85 | G10: =F10 -> 277.85 | H10: =G10 -> 277.85 | I10: =H10 -> 277.85 | J10: =I10 -> 277.85
B11: AGR_DEM_LIV_SWINE | C11: PL | D11: =E76/1000 -> 11727.41 | E11: =D11 -> 11727.41 | F11: =E11 -> 11727.41 | G11: =F11 -> 11727.41 | H11: =G11 -> 11727.41 | I11: =H11 -> 11727.41 | J11: =I11 -> 11727.41
B12: AGR_DEM_LIV_GOAT | C12: PL | D12: =I76/1000 -> 62.581 | E12: =D12 -> 62.581 | F12: =E12 -> 62.581 | G12: =F12 -> 62.581 | H12: =G12 -> 62.581 | I12: =H12 -> 62.581 | J12: =I12 -> 62.581
B13: AGR_DEM_LIV_POULTRY | C13: PL | D13: =D82/1000 -> 205774.51 | E13: =D13 -> 205774.51 | F13: =E13 -> 205774.51 | G13: =F13 -> 205774.51 | H13: =G13 -> 205774.51 | I13: =H13 -> 205774.51 | J13: =I13 -> 205774.51
B14: \I: | D14: area in thousands ha
B15: AGR_DEM_CROP_WHEAT | C15: PL | D15: =C40 -> 2373.3 | E15: =D15 -> 2373.3 | F15: =E15 -> 2373.3 | G15: =F15 -> 2373.3 | H15: =G15 -> 2373.3 | I15: =H15 -> 2373.3 | J15: =I15 -> 2373.3
B16: AGR_DEM_CROP_BARLEY | C16: PL | D16: =C44 -> 675.3 | E16: =D16 -> 675.3 | F16: =E16 -> 675.3 | G16: =F16 -> 675.3 | H16: =G16 -> 675.3 | I16: =H16 -> 675.3 | J16: =I16 -> 675.3
B17: AGR_DEM_CROP_MAIZE | C17: PL | D17: =C52 -> 946.1 | E17: =D17 -> 946.1 | F17: =E17 -> 946.1 | G17: =F17 -> 946.1 | H17: =G17 -> 946.1 | I17: =H17 -> 946.1 | J17: =I17 -> 946.1
B18: AGR_DEM_CROP_CER-MIX | C18: PL | D18: =C50 -> 590.9 | E18: =D18 -> 590.9 | F18: =E18 -> 590.9 | G18: =F18 -> 590.9 | H18: =G18 -> 590.9 | I18: =H18 -> 590.9 | J18: =I18 -> 590.9
B19: AGR_DEM_CROP_TRITICALE | C19: PL | D19: =C48 -> 1389 | E19: =D19 -> 1389 | F19: =E19 -> 1389 | G19: =F19 -> 1389 | H19: =G19 -> 1389 | I19: =H19 -> 1389 | J19: =I19 -> 1389
B20: AGR_DEM_CROP_OATS | C20: PL | D20: =C46 -> 500.1 | E20: =D20 -> 500.1 | F20: =E20 -> 500.1 | G20: =F20 -> 500.1 | H20: =G20 -> 500.1 | I20: =H20 -> 500.1 | J20: =I20 -> 500.1
B21: AGR_DEM_CROP_RYE | C21: PL | D21: =C42 -> 843.6 | E21: =D21 -> 843.6 | F21: =E21 -> 843.6 | G21: =F21 -> 843.6 | H21: =G21 -> 843.6 | I21: =H21 -> 843.6 | J21: =I21 -> 843.6
B22: AGR_DEM_CROP_MILL-BUCK | C22: PL | D22: =C54+C56 -> 90.4 | E22: =D22 -> 90.4 | F22: =E22 -> 90.4 | G22: =F22 -> 90.4 | H22: =G22 -> 90.4 | I22: =H22 -> 90.4 | J22: =I22 -> 90.4
B23: AGR_DEM_CROP_PULS-FEED | C23: PL | D23: =C64 -> 18 | E23: =D23 -> 18 | F23: =E23 -> 18 | G23: =F23 -> 18 | H23: =G23 -> 18 | I23: =H23 -> 18 | J23: =I23 -> 18
B24: AGR_DEM_CROP_PULS-EDIB | C24: PL | D24: =C62 -> 82.9 | E24: =D24 -> 82.9 | F24: =E24 -> 82.9 | G24: =F24 -> 82.9 | H24: =G24 -> 82.9 | I24: =H24 -> 82.9 | J24: =I24 -> 82.9
B25: AGR_DEM_CROP_POTATO | C25: PL | D25: =C58 -> 225.7 | E25: =D25 -> 225.7 | F25: =E25 -> 225.7 | G25: =F25 -> 225.7 | H25: =G25 -> 225.7 | I25: =H25 -> 225.7 | J25: =I25 -> 225.7
B26: AGR_DEM_CROP_OIL | C26: PL | D26: =C60 -> 1039.3 | E26: =D26 -> 1039.3 | F26: =E26 -> 1039.3 | G26: =F26 -> 1039.3 | H26: =G26 -> 1039.3 | I26: =H26 -> 1039.3 | J26: =I26 -> 1039.3
B27: AGR_DEM_CROP_FRUIT | C27: PL | D27: 0 | E27: =D27 -> 0 | F27: =E27 -> 0 | G27: =F27 -> 0 | H27: =G27 -> 0 | I27: =H27 -> 0 | J27: =I27 -> 0
B28: AGR_DEM_CROP_VEG | C28: PL | D28: 0 | E28: =D28 -> 0 | F28: =E28 -> 0 | G28: =F28 -> 0 | H28: =G28 -> 0 | I28: =H28 -> 0 | J28: =I28 -> 0
B33: Dane wejściowe:
B35: Produkcja upraw rolnych i ogrodniczych w 2020 r. | H35: GUS
B37: Wyszczególnienie | C37: Powierzchnia w tys. ha | D37: Plony z 1 ha w dt | E37: Zbiory w dt | F37: Powierzchnia | G37: Plony | H37: Zbiory
F38: 2019 = 100
B39: TABL. 4. POWIERZCHNIA, PLONY I ZBIORY PSZENICY OGÓŁEM
B40: P o l s k a .................... | C40: 2373.3 | D40: 53.4 | E40: 126689067 | F40: 94.5 | G40: 121.6 | H40: 115
B41: TABL. 7. POWIERZCHNIA, PLONY I ZBIORY ŻYTA
B42: P o l s k a ..................... | C42: 843.6 | D42: 35.1 | E42: 29597519 | F42: 93.3 | G42: 129 | H42: 120.2
B43: TABL. 8. POWIERZCHNIA, PLONY I ZBIORY JĘCZMIENIA OGÓŁEM
B44: P o l s k a ..................... | C44: 675.3 | D44: 44.4 | E44: 30006221 | F44: 69.2 | G44: 128.3 | H44: 88.9
B45: TABL. 11. POWIERZCHNIA, PLONY I ZBIORY OWSA
B46: P o l s k a .................... | C46: 500.1 | D46: 33.2 | E46: 16579863 | F46: 100.9 | G46: 133.3 | H46: 134.5
B47: TABL. 12. POWIERZCHNIA, PLONY I ZBIORY PSZENŻYTA OGÓŁEM
B48: P o l s k a ..................... | C48: 1389 | D48: 44.6 | E48: 61952359 | F48: 105.6 | G48: 127.8 | H48: 135.2
...

Sheet OLD_AGR_DEMAND
B4: CommName | C4: Region | D4: 2020 | F4: 2025 | G4: 2030 | H4: 2035 | I4: 2040 | J4: 2045 | K4: 2050
B5: \I: | D5: IPI | F5: IPI | G5: IPI | H5: IPI | I5: IPI | J5: IPI | K5: IPI
B6: AGR_DEM | C6: PL | D6: 100 | F6: 100 | G6: 100 | H6: 100 | I6: 100 | J6: 100 | K6: 100
B7: \I: | D7: thousands of animals
B8: AGR_DEM_LIV_CAT_DAIRY | C8: PL | D8: 85.388 | F8: 85.388 | G8: 85.388 | H8: 85.388 | I8: 85.388 | J8: 85.388 | K8: 85.388
B9: AGR_DEM_LIV_CAT_NON-DAIRY | C9: PL | D9: 93.213 | F9: 93.213 | G9: 93.213 | H9: 93.213 | I9: 93.213 | J9: 93.213 | K9: 93.213
B10: AGR_DEM_LIV_SHEEP | C10: PL | D10: 79.092 | F10: 79.092 | G10: 79.092 | H10: 79.092 | I10: 79.092 | J10: 79.092 | K10: 79.092
B11: AGR_DEM_LIV_SWINE | C11: PL | D11: 141.443 | F11: 141.443 | G11: 141.443 | H11: 141.443 | I11: 141.443 | J11: 141.443 | K11: 141.443
B12: AGR_DEM_LIV_GOAT | C12: PL | D12: 4.9765253 | F12: 4.9765253 | G12: 4.9765253 | H12: 4.9765253 | I12: 4.9765253 | J12: 4.9765253 | K12: 4.9765253
B13: \I: AGR_DEM_LIV_HORSE | C13: PL | D13: 20.306 | F13: 20.306 | G13: 20.306 | H13: 20.306 | I13: 20.306 | J13: 20.306 | K13: 20.306
B14: AGR_DEM_LIV_POULTRY | C14: PL | D14: 5170.067 | F14: 5170.067 | G14: 5170.067 | H14: 5170.067 | I14: 5170.067 | J14: 5170.067 | K14: 5170.067
B15: \I: AGR_DEM_LIV_RABBIT | C15: PL | D15: 17.32 | F15: 17.32 | G15: 17.32 | H15: 17.32 | I15: 17.32 | J15: 17.32 | K15: 17.32
B16: \I: AGR_DEM_LIV_FUR | C16: PL | D16: 16.899 | F16: 16.899 | G16: 16.899 | H16: 16.899 | I16: 16.899 | J16: 16.899 | K16: 16.899
B17: \I: AGR_DEM_LIV_INDIRECT | C17: PL | D17: 5628.7045 | F17: 5628.7045 | G17: 5628.7045 | H17: 5628.7045 | I17: 5628.7045 | J17: 5628.7045 | K17: 5628.7045

Sheet COM_DEMAND
B3: ~FI_T:DEMAND
B4: CommName | C4: Region | D4: 2020 | E4: 2025 | F4: 2030 | G4: 2035 | H4: 2040 | I4: 2045 | J4: 2050
B5: \I: | D5: IPI | E5: IPI | F5: IPI | G5: IPI | H5: IPI | I5: IPI | J5: IPI
B6: COM_DEM | C6: PL | D6: 100 | E6: 112.793 | F6: 121.637 | G6: 126.4 | H6: 128.595 | I6: 129.716 | J6: 130.266
E8: =(E6-D6)/D6 -> 0.12793 | F8: =(F6-E6)/E6 -> 0.078409121 | G8: =(G6-F6)/F6 -> 0.039157493 | H8: =(H6-G6)/G6 -> 0.017365506 | I8: =(I6-H6)/H6 -> 0.0087172907 | J8: =(J6-I6)/I6 -> 0.0042400321
E10: =(E6-100)/100 -> 0.12793 | F10: =(F6-100)/100 -> 0.21637 | G10: =(G6-100)/100 -> 0.264 | H10: =(H6-100)/100 -> 0.28595 | I10: =(I6-100)/100 -> 0.29716 | J10: =(J6-100)/100 -> 0.30266

Sheet GUS_2020_HT_ELC
A1: Tabl. 4(94) Bilans całkowity (2020)
A2: Table 4(94) Complete balance (2020)
A3: WYSZCZEGÓLNIENIE | B3: Energia cieplna | C3: Energia elektryczna | D3: Energia cieplna | E3: Energia elektryczna
A4: SPECIFICATION | B4: Heat | C4: Electricity | D4: Heat | E4: Electricity
B5: PJ | D5: TWh
A6: Pozyskanie Primary production | B6: 1.130436 | D6: =IF(B6<>"",B6/3.6,"") -> 0.31401 | E6: =IF(C6<>"",C6/3.6,"") | F6: =IF(C6<>"",C6/3.6,"")
A7: Produkty z odzysku Recovered & recycled products | D7: =IF(B7<>"",B7/3.6,"") | E7: =IF(C7<>"",C7/3.6,"")
A8: Import Imports | C8: 74.231964 | D8: =IF(B8<>"",B8/3.6,"") | E8: =IF(C8<>"",C8/3.6,"") -> 20.61999
A9: Eksport Exports | C9: 26.502444 | D9: =IF(B9<>"",B9/3.6,"") | E9: =IF(C9<>"",C9/3.6,"") -> 7.36179
A10: Zmiana zapasów Change in stock | D10: =IF(B10<>"",B10/3.6,"") | E10: =IF(C10<>"",C10/3.6,"")
A11: Energia dostępna brutto Gross available energy | B11: 1.130436 | C11: 47.771388 | D11: =IF(B11<>"",B11/3.6,"") -> 0.31401 | E11: =IF(C11<>"",C11/3.6,"") -> 13.26983
A12: Międzynarodowy bunkier morski International maritime bunkers | D12: =IF(B12<>"",B12/3.6,"") | E12: =IF(C12<>"",C12/3.6,"")
A13: Krajowe zużycie brutto Gross inland consumption | B13: 1.130436 | C13: 47.771388 | D13: =IF(B13<>"",B13/3.6,"") -> 0.31401 | E13: =IF(C13<>"",C13/3.6,"") -> 13.26983
A14: Transport lotniczy międzynarodowy International aviation | D14: =IF(B14<>"",B14/3.6,"") | E14: =IF(C14<>"",C14/3.6,"")
A15: Całkowita podaż energii Total energy supply | B15: 1.130436 | C15: 47.771388 | D15: =IF(B15<>"",B15/3.6,"") -> 0.31401 | E15: =IF(C15<>"",C15/3.6,"") -> 13.26983
A16: Krajowe zużycie brutto (Europa 2020-2030) Gross inland consumption (Europe 2020-2030) | D16: =IF(B16<>"",B16/3.6,"") | E16: =IF(C16<>"",C16/3.6,"")
A17: Zużycie energii pierwotnej (Europa 2020-2030) Primary energy consumption (Europe 2020-2030) | D17: =IF(B17<>"",B17/3.6,"") | E17: =IF(C17<>"",C17/3.6,"")
A18: Zużycie końcowe energii (Europa 2020-2030) Final energy consumption (Europe 2020-2030) | D18: =IF(B18<>"",B18/3.6,"") | E18: =IF(C18<>"",C18/3.6,"")
A19: Wsad przemian Transformation input | B19: 1.758456 | C19: 4.270536 | D19: =IF(B19<>"",B19/3.6,"") -> 0.48846 | E19: =IF(C19<>"",C19/3.6,"") -> 1.18626
A20: Wytwarzanie energii elektrycznej i ciepła Electricity & heat generation | B20: 1.758456 | C20: 4.270536 | D20: =IF(B20<>"",B20/3.6,"") -> 0.48846 | E20: =IF(C20<>"",C20/3.6,"") -> 1.18626
A21: Elektrownie zawodowe Main activity producer electricity only | D21: =IF(B21<>"",B21/3.6,"") | E21: =IF(C21<>"",C21/3.6,"")
A22: Instalacje elektrociepłowni zawodowych Main activity producer CHP | D22: =IF(B22<>"",B22/3.6,"") | E22: =IF(C22<>"",C22/3.6,"")
A23: Ciepłownie zawodowe Main activity producer heat only | D23: =IF(B23<>"",B23/3.6,"") | E23: =IF(C23<>"",C23/3.6,"")
A24: Elektrownie przemysłowe Autoproducer electricity only | D24: =IF(B24<>"",B24/3.6,"") | E24: =IF(C24<>"",C24/3.6,"")
A25: Instalacje elektrociepłowni przemysłowych Autoproducer CHP | B25: 1.130436 | D25: =IF(B25<>"",B25/3.6,"") -> 0.31401 | E25: =IF(C25<>"",C25/3.6,"")
A26: Ciepłownie przemysłowe Autoproducer heat only | D26: =IF(B26<>"",B26/3.6,"") | E26: =IF(C26<>"",C26/3.6,"")
A27: Pompy ciepła Electrically driven heat pumps | C27: 0 | D27: =IF(B27<>"",B27/3.6,"") | E27: =IF(C27<>"",C27/3.6,"") -> 0
A28: Kotły elektryczne Electric boilers | D28: =IF(B28<>"",B28/3.6,"") | E28: =IF(C28<>"",C28/3.6,"")
A29: Elektrownie szczytowo-pompowe Electricity for pumped storage | C29: 4.270536 | D29: =IF(B29<>"",B29/3.6,"") | E29: =IF(C29<>"",C29/3.6,"") -> 1.18626
A30: Ciepło wykorzystane do produkcji energii elektrycznej Derived heat for electricity production | B30: 0.62802 | D30: =IF(B30<>"",B30/3.6,"") -> 0.17445 | E30: =IF(C30<>"",C30/3.6,"")
A31: Koksownie Coke ovens | D31: =IF(B31<>"",B31/3.6,"") | E31: =IF(C31<>"",C31/3.6,"")
A32: Wielkie piece Blast furnaces | D32: =IF(B32<>"",B32/3.6,"") | E32: =IF(C32<>"",C32/3.6,"")
A33: Gazownie Gas works | D33: =IF(B33<>"",B33/3.6,"") | E33: =IF(C33<>"",C33/3.6,"")
A34: Rafinerie Refineries & petrochemical industry | D34: =IF(B34<>"",B34/3.6,"") | E34: =IF(C34<>"",C34/3.6,"")
A35: Wsad do rafinerii Refinery intake | D35: =IF(B35<>"",B35/3.6,"") | E35: =IF(C35<>"",C35/3.6,"")
A36: Zwroty z sektora petrochemicznego Backflows from petrochemical industry | D36: =IF(B36<>"",B36/3.6,"") | E36: =IF(C36<>"",C36/3.6,"")
A37: Produkty przetwarzane Products transferred | D37: =IF(B37<>"",B37/3.6,"") | E37: =IF(C37<>"",C37/3.6,"")
A38: Produkty przeklasyfikowane Interproduct transfers | D38: =IF(B38<>"",B38/3.6,"") | E38: =IF(C38<>"",C38/3.6,"")
A39: Zużycie bezpośrednie Direct use | D39: =IF(B39<>"",B39/3.6,"") | E39: =IF(C39<>"",C39/3.6,"")
A40: Wsad do przemysłu petrochemicznego Petrochemical industry intake | D40: =IF(B40<>"",B40/3.6,"") | E40: =IF(C40<>"",C40/3.6,"")
...
